Workbook
Name Fluvius_Voltage: 'BACKEND Connection Types'!$B$2:$B$3
Name Resa_Voltage: 'BACKEND Connection Types'!$E$2
Name Sibelga_Voltage: 'BACKEND Connection Types'!$C$2
Name Elia_Voltage: 'BACKEND Connection Types'!$A$2:$A$4
Name Orese_Voltage: 'BACKEND Connection Types'!$D$2

Sheet Intro
B5: Title | C5: Calculation Grid Fees - Belgium - BESS Focus
B6: Recipient | C6: Internal Document
B7: Flexcity Contact | C7: Anna Hutse, Aron Vanneste
B8: Date | C8: 46043
B10: Note: This sheet is intended for indicative purposes. Actual grid fees may vary based on specific contractual arrangements and regulatory changes.
B12: Description
B13: This sheet provides a comprehensive overview of grid fees for all Belgian DSOs (Fluvius, Ores, Resa, Sibelga) and the TSO (Elia) for the year 2026. The Calculator tab determines annual grid fees based on: - DSO/TSO selection (with regional breakdown for Fluvius) - Voltage level & Connection type - Connection capacity (MVA) - Annual peak demand (MW) - Monthly peak demand (MW) - Energy consumption (MWh) Two calculation scenarios are provided: 1. Without exemptions: Standard grid fees 2. With BESS exemptions: Reduced grid fees for battery energy storage systems under Belgian regulatory exemptions Additional tabs: - Visualisation tab: Interactive charts showing cost breakdown per fee component for both scenarios (automatically updates based on Calculator inputs) - Methodology tab: Calculation rules per DSO/TSO (specifically for peak & volumetric) and an overview of excluded costs and applied BESS exemptions - Details tab: Complete overview of grid fee components, sources, and all regulatory exemptions - BESS Example tab: Reference case for a 1MW/2MWh BESS system operating 1.5 cycles per day (for Fluvius: the region Midden-Vlaanderen was used) - BACKEND tabs: Data sources (Fees Database, BESS Exemptions, Connection Types)

Sheet Calculator
B2: INPUT | F2: Input for BESS 1 MW/2MWh, 1.5 cycles per day
B3: DSO/TSO Selection | C3: Elia | F3: Yearly Consumption (MWh/y) | G3: =1*2*1.5*365 -> 1095
B4: Region | C4: N/A | F4: Monthly Peak Demand (MW) | G4: 1
B5: Voltage Level | F5: Annual Peak Demand (MW) | G5: 1
B6: Connection Type | F6: Contracted Capacity (MVA) | G6: 1
B7: Yearly Consumption Offtake (MWh/y) | C7: 1095
B8: Yearly Consumption Injection (MWh/y) | C8: 1027
B9: Monthly Peak Demand (MW) | C9: 1.5
B10: Annual Peak Demand (MW) | C10: 1.5
B11: Contracted Capacity (MVA) | C11: 1
B13: CALCULATION WITHOUT EXEMPTIONS | F13: CALCULATION WITH EXEMPTIONS FOR BESS
B14: Injection Fixed | C14: =IFERROR(__xludf.DUMMYFUNCTION("IF(C6=""N/A"", IFERROR(INDEX(FILTER('BACKEND Fees Database'!F:F, ('BACKEND Fees Database'!B:B=C3)*('BACKEND Fees Database'!C:C=IF(C3=""Fluvius"",C4,""""))*('BACKEND Fees Database'!D:D=C5)), 1), 0), IFERROR(INDEX(FILTER('BACKEND Fees Database'!F:F, ('"&"BACKEND Fees Database'!B:B=C3)*('BACKEND Fees Database'!C:C=IF(C3=""Fluvius"",C4,""""))*('BACKEND Fees Database'!D:D=C5)*('BACKEND Fees Database'!E:E=C6)), 1), 0) ) "),0.0) -> 0 | D14: k€/y | F14: Injection Fixed | G14: =IFERROR(__xludf.DUMMYFUNCTION("C14 * IFERROR(INDEX(FILTER('BACKEND BESS Exemptions'!C:C, ('BACKEND BESS Exemptions'!A:A=C3)*('BACKEND BESS Exemptions'!B:B=""Injection Fixed"")), 1), 0)"),0.0) -> 0 | H14: k€/y
B15: Injection Contracted | C15: =IFERROR(__xludf.DUMMYFUNCTION("IF(C6=""N/A"", IFERROR(INDEX(FILTER('BACKEND Fees Database'!G:G, ('BACKEND Fees Database'!B:B=C3)*('BACKEND Fees Database'!C:C=IF(C3=""Fluvius"",C4,""""))*('BACKEND Fees Database'!D:D=C5)), 1) * C11, 0), IFERROR(INDEX(FILTER('BACKEND Fees Database'!G:"&"G, ('BACKEND Fees Database'!B:B=C3)*('BACKEND Fees Database'!C:C=IF(C3=""Fluvius"",C4,""""))*('BACKEND Fees Database'!D:D=C5)*('BACKEND Fees Database'!E:E=C6)), 1) * C11, 0) ) "),0.0) -> 0 | D15: k€/y | F15: Injection Contracted | G15: =IFERROR(__xludf.DUMMYFUNCTION("C15 * IFERROR(INDEX(FILTER('BACKEND BESS Exemptions'!C:C, ('BACKEND BESS Exemptions'!A:A=C3)*('BACKEND BESS Exemptions'!B:B=""Injection Contracted"")), 1), 0) "),0.0) -> 0 | H15: k€/y
B16: Injection Peak Monthly | C16: =IFERROR(__xludf.DUMMYFUNCTION("IF(C6=""N/A"", IFERROR(INDEX(FILTER('BACKEND Fees Database'!H:H, ('BACKEND Fees Database'!B:B=C3)*('BACKEND Fees Database'!C:C=IF(C3=""Fluvius"",C4,""""))*('BACKEND Fees Database'!D:D=C5)), 1) * C9, 0), IFERROR(INDEX(FILTER('BACKEND Fees Database'!H:H"&", ('BACKEND Fees Database'!B:B=C3)*('BACKEND Fees Database'!C:C=IF(C3=""Fluvius"",C4,""""))*('BACKEND Fees Database'!D:D=C5)*('BACKEND Fees Database'!E:E=C6)), 1) * C9, 0) ) "),0.0) -> 0 | D16: k€/y | F16: Injection Peak Monthly | G16: =IFERROR(__xludf.DUMMYFUNCTION("C16 * IFERROR(INDEX(FILTER('BACKEND BESS Exemptions'!C:C, ('BACKEND BESS Exemptions'!A:A=C3)*('BACKEND BESS Exemptions'!B:B=""Injection Peak Monthly"")), 1), 0) "),0.0) -> 0 | H16: k€/y | K16: Please allow a moment for the calculator to refresh after making a dropdown selection
B17: Injection Peak Yearly | C17: =IFERROR(__xludf.DUMMYFUNCTION("IF(C6=""N/A"", IFERROR(INDEX(FILTER('BACKEND Fees Database'!I:I, ('BACKEND Fees Database'!B:B=C3)*('BACKEND Fees Database'!C:C=IF(C3=""Fluvius"",C4,""""))*('BACKEND Fees Database'!D:D=C5)), 1) * C10, 0), IFERROR(INDEX(FILTER('BACKEND Fees Database'!I:"&"I, ('BACKEND Fees Database'!B:B=C3)*('BACKEND Fees Database'!C:C=IF(C3=""Fluvius"",C4,""""))*('BACKEND Fees Database'!D:D=C5)*('BACKEND Fees Database'!E:E=C6)), 1) * C10, 0) ) "),0.0) -> 0 | D17: k€/y | F17: Injection Peak Yearly | G17: =IFERROR(__xludf.DUMMYFUNCTION("C17 * IFERROR(INDEX(FILTER('BACKEND BESS Exemptions'!C:C, ('BACKEND BESS Exemptions'!A:A=C3)*('BACKEND BESS Exemptions'!B:B=""Injection Peak Yearly"")), 1), 0) "),0.0) -> 0 | H17: k€/y
B18: Injection Volumetric | C18: =IFERROR(__xludf.DUMMYFUNCTION("IF(C6=""N/A"", IFERROR(INDEX(FILTER('BACKEND Fees Database'!J:J, ('BACKEND Fees Database'!B:B=C3)*('BACKEND Fees Database'!C:C=IF(C3=""Fluvius"",C4,""""))*('BACKEND Fees Database'!D:D=C5)), 1) * C8, 0), IFERROR(INDEX(FILTER('BACKEND Fees Database'!J:J"&", ('BACKEND Fees Database'!B:B=C3)*('BACKEND Fees Database'!C:C=IF(C3=""Fluvius"",C4,""""))*('BACKEND Fees Database'!D:D=C5)*('BACKEND Fees Database'!E:E=C6)), 1) * C8, 0) ) "),0.0) -> 0 | D18: k€/y | F18: Injection Volumetric | G18: =IFERROR(__xludf.DUMMYFUNCTION("C18 * IFERROR(INDEX(FILTER('BACKEND BESS Exemptions'!C:C, ('BACKEND BESS Exemptions'!A:A=C3)*('BACKEND BESS Exemptions'!B:B=""Injection Volumetric"")), 1), 0)"),0.0) -> 0 | H18: k€/y
B19: Injection Other | C19: =IFERROR(__xludf.DUMMYFUNCTION("IF(C6=""N/A"", IFERROR(INDEX(FILTER('BACKEND Fees Database'!K:K, ('BACKEND Fees Database'!B:B=C3)*('BACKEND Fees Database'!C:C=IF(C3=""Fluvius"",C4,""""))*('BACKEND Fees Database'!D:D=C5)), 1) * C8, 0), IFERROR(INDEX(FILTER('BACKEND Fees Database'!K:K"&", ('BACKEND Fees Database'!B:B=C3)*('BACKEND Fees Database'!C:C=IF(C3=""Fluvius"",C4,""""))*('BACKEND Fees Database'!D:D=C5)*('BACKEND Fees Database'!E:E=C6)), 1) * C8, 0) ) "),0.0) -> 0 | D19: k€/y | F19: Injection Other | G19: =IFERROR(__xludf.DUMMYFUNCTION("C19 * IFERROR(INDEX(FILTER('BACKEND BESS Exemptions'!C:C, ('BACKEND BESS Exemptions'!A:A=C3)*('BACKEND BESS Exemptions'!B:B=""Injection Other"")), 1), 0)"),0.0) -> 0 | H19: k€/y
B20: Offtake Fixed | C20: =IFERROR(__xludf.DUMMYFUNCTION("IF(C6=""N/A"", IFERROR(INDEX(FILTER('BACKEND Fees Database'!L:L, ('BACKEND Fees Database'!B:B=C3)*('BACKEND Fees Database'!C:C=IF(C3=""Fluvius"",C4,""""))*('BACKEND Fees Database'!D:D=C5)), 1), 0), IFERROR(INDEX(FILTER('BACKEND Fees Database'!L:L, ('"&"BACKEND Fees Database'!B:B=C3)*('BACKEND Fees Database'!C:C=IF(C3=""Fluvius"",C4,""""))*('BACKEND Fees Database'!D:D=C5)*('BACKEND Fees Database'!E:E=C6)), 1), 0) ) "),0.0) -> 0 | D20: k€/y | F20: Offtake Fixed | G20: =IFERROR(__xludf.DUMMYFUNCTION("C20 * IFERROR(INDEX(FILTER('BACKEND BESS Exemptions'!C:C, ('BACKEND BESS Exemptions'!A:A=C3)*('BACKEND BESS Exemptions'!B:B=""Offtake Fixed"")), 1), 0)"),0.0) -> 0 | H20: k€/y
B21: Offtake Contracted | C21: =IFERROR(__xludf.DUMMYFUNCTION("IF(C6=""N/A"", IFERROR(INDEX(FILTER('BACKEND Fees Database'!M:M, ('BACKEND Fees Database'!B:B=C3)*('BACKEND Fees Database'!C:C=IF(C3=""Fluvius"",C4,""""))*('BACKEND Fees Database'!D:D=C5)), 1) * C11, 0), IFERROR(INDEX(FILTER('BACKEND Fees Database'!M:"&"M, ('BACKEND Fees Database'!B:B=C3)*('BACKEND Fees Database'!C:C=IF(C3=""Fluvius"",C4,""""))*('BACKEND Fees Database'!D:D=C5)*('BACKEND Fees Database'!E:E=C6)), 1) * C11, 0) ) "),0.0) -> 0 | D21: k€/y | F21: Offtake Contracted | G21: =IFERROR(__xludf.DUMMYFUNCTION("C21 * IFERROR(INDEX(FILTER('BACKEND BESS Exemptions'!C:C, ('BACKEND BESS Exemptions'!A:A=C3)*('BACKEND BESS Exemptions'!B:B=""Offtake Contracted"")), 1), 0)"),0.0) -> 0 | H21: k€/y
B22: Offtake Peak Monthly | C22: =IFERROR(__xludf.DUMMYFUNCTION("IF(C6=""N/A"", IFERROR(INDEX(FILTER('BACKEND Fees Database'!N:N, ('BACKEND Fees Database'!B:B=C3)*('BACKEND Fees Database'!C:C=IF(C3=""Fluvius"",C4,""""))*('BACKEND Fees Database'!D:D=C5)), 1) * C9, 0), IFERROR(INDEX(FILTER('BACKEND Fees Database'!N:N"&", ('BACKEND Fees Database'!B:B=C3)*('BACKEND Fees Database'!C:C=IF(C3=""Fluvius"",C4,""""))*('BACKEND Fees Database'!D:D=C5)*('BACKEND Fees Database'!E:E=C6)), 1) * C9, 0) ) "),0.0) -> 0 | D22: k€/y | F22: Offtake Peak Monthly | G22: =IFERROR(__xludf.DUMMYFUNCTION("C22 * IFERROR(INDEX(FILTER('BACKEND BESS Exemptions'!C:C, ('BACKEND BESS Exemptions'!A:A=C3)*('BACKEND BESS Exemptions'!B:B=""Offtake Peak Monthly"")), 1), 0)"),0.0) -> 0 | H22: k€/y
B23: Offtake Peak Yearly | C23: =IFERROR(__xludf.DUMMYFUNCTION("IF(C6=""N/A"", IFERROR(INDEX(FILTER('BACKEND Fees Database'!O:O, ('BACKEND Fees Database'!B:B=C3)*('BACKEND Fees Database'!C:C=IF(C3=""Fluvius"",C4,""""))*('BACKEND Fees Database'!D:D=C5)), 1) * C10, 0), IFERROR(INDEX(FILTER('BACKEND Fees Database'!O:"&"O, ('BACKEND Fees Database'!B:B=C3)*('BACKEND Fees Database'!C:C=IF(C3=""Fluvius"",C4,""""))*('BACKEND Fees Database'!D:D=C5)*('BACKEND Fees Database'!E:E=C6)), 1) * C10, 0) ) "),0.0) -> 0 | D23: k€/y | F23: Offtake Peak Yearly | G23: =IFERROR(__xludf.DUMMYFUNCTION("C23 * IFERROR(INDEX(FILTER('BACKEND BESS Exemptions'!C:C, ('BACKEND BESS Exemptions'!A:A=C3)*('BACKEND BESS Exemptions'!B:B=""Offtake Peak Yearly"")), 1), 0)"),0.0) -> 0 | H23: k€/y
B24: Offtake Volumetric | C24: =IFERROR(__xludf.DUMMYFUNCTION("IF(C6=""N/A"", IFERROR(INDEX(FILTER('BACKEND Fees Database'!P:P, ('BACKEND Fees Database'!B:B=C3)*('BACKEND Fees Database'!C:C=IF(C3=""Fluvius"",C4,""""))*('BACKEND Fees Database'!D:D=C5)), 1) * C7, 0), IFERROR(INDEX(FILTER('BACKEND Fees Database'!P:P"&", ('BACKEND Fees Database'!B:B=C3)*('BACKEND Fees Database'!C:C=IF(C3=""Fluvius"",C4,""""))*('BACKEND Fees Database'!D:D=C5)*('BACKEND Fees Database'!E:E=C6)), 1) * C7, 0) ) "),0.0) -> 0 | D24: k€/y | F24: Offtake Volumetric | G24: =IFERROR(__xludf.DUMMYFUNCTION("C24 * IFERROR(INDEX(FILTER('BACKEND BESS Exemptions'!C:C, ('BACKEND BESS Exemptions'!A:A=C3)*('BACKEND BESS Exemptions'!B:B=""Offtake Volumetric"")), 1), 0)"),0.0) -> 0 | H24: k€/y
B25: Offtake Other | C25: =IFERROR(__xludf.DUMMYFUNCTION("IF(C6=""N/A"", IFERROR(INDEX(FILTER('BACKEND Fees Database'!Q:Q, ('BACKEND Fees Database'!B:B=C3)*('BACKEND Fees Database'!C:C=IF(C3=""Fluvius"",C4,""""))*('BACKEND Fees Database'!D:D=C5)), 1) * C7, 0), IFERROR(INDEX(FILTER('BACKEND Fees Database'!Q:Q"&", ('BACKEND Fees Database'!B:B=C3)*('BACKEND Fees Database'!C:C=IF(C3=""Fluvius"",C4,""""))*('BACKEND Fees Database'!D:D=C5)*('BACKEND Fees Database'!E:E=C6)), 1) * C7, 0) ) "),0.0) -> 0 | D25: k€/y | F25: Offtake Other | G25: =IFERROR(__xludf.DUMMYFUNCTION("C25 * IFERROR(INDEX(FILTER('BACKEND BESS Exemptions'!C:C, ('BACKEND BESS Exemptions'!A:A=C3)*('BACKEND BESS Exemptions'!B:B=""Offtake Other"")), 1), 0)"),0.0) -> 0 | H25: k€/y
B26: TOTAL | C26: =SUM(C14:C25) -> 0 | D26: k€/y | F26: TOTAL | G26: =SUM(G14:G25) -> 0 | H26: k€/y

Sheet Visualisation
C2: DSO/TSO Selection | D2: Region | E2: Voltage Level | F2: Connection Type | G2: Yearly Consumption (MWh/y) | H2: Monthly Peak Demand (MW) | I2: Annual Peak Demand (MW) | J2: Contracted Capacity (MVA)
C3: =Calculator!C3 -> Elia | D3: =Calculator!C4 -> N/A | E3: =Calculator!C5 | F3: =Calculator!C6 | G3: =Calculator!C7 -> 1095 | H3: =Calculator!C9 -> 1.5 | I3: =Calculator!C10 -> 1.5 | J3: =Calculator!C11 -> 1

Sheet Methodology
B1: All calculations in this sheet are excluding VAT
B3: Costs not taken into account
B4: Fees for (additional) reactive energy
B5: Fees for exceeding access power (in this sheet referred to as contracted capacity)
B6: Fees for imbalance compensation tariffs (specifically for Elia)
B7: Fees for market integration (specifically for Elia)
B9: Details about calculations
B10: Offtake Monthly Peak Elia | C10: monthly peak applied to the 11th measured peak of the month (only if specifically connected to the Elia grid or DSO connected to 30/36/70-kV network). Quarter-hours during the monthly peak demand-reduction period (April to September, weekends, 10 a.m. to 7 p.m.) are excluded from the monthly peak calculation.
B11: Offtake Annual Peak Elia | C11: Annual peak applied to the highest measured peak during the annual peak tariff period in the previous 12 months, after excluding the 10 highest peaks measured each month (only if specifically connected to the Elia grid or DSO connected to 30/36/70-kV network). The annual peak tariff period is defined as January to March and November to December, from 5 p.m. to 8 p.m., excluding weekends and public holidays."
B12: Offtake Annual Peak Sibelga | C12: Capacity rate multiplied by degression factor E1
B13: Offtake Volumetric Sibelga | C13: fees are split into HI and LO HI: 0.0044466 LO: 0.0026680 --> for these calculations the average was taken
B14: Offtake Annual Peak Ores | C14: Multiply by 1/3 of highest monthly peak from the past 12 months
B15: Offtake Monthly Peak Ores | C15: Multiply by 2/3 of 11th highest quarterly peak of the month OR (if insufficient data) multiply by 2/3 of the maximum measured peak power during the month
B16: Offtake Volumetric Resa | C16: fees are split into HI and LO: HI: 0.0005446 LO: 0.0002178" --> for these calculations the average was taken
B17: Offtake Volumetric Resa | C17: fees are split into HI and LO: HI: 0.0005446 LO: 0.0002178" --> for these calculations the average was taken
B18: Offtake Monthly Peak Resa | C18: Multiply by 2/3 of 11th highest quarterly peak of the month OR (if insufficient data) multiply by 2/3 of the maximum measured peak power during the month
B19: Offtake Annual Peak Resa | C19: Multiply by 1/3 of highest monthly peak from the past 12 months
B21: BESS Exemptions taken into account
B22: Elia | C22: Offtake | D22: Electricity storage facilities: New storage facilities (commissioned after July 1, 2018): 100% exemption from all transmission tariffs (except connection tariffs) for 10 years following initial commissioning.
B23: Fluvius | C23: Offtake | D23: -Stand-alone stationary storage systems: • 80% reduction on the contracted capacity and peak monthly tariff (exceeding capacity tariff as well but not included in these calculations • 100% exemption from volumetric tariff (tariff for PSO & surcharges)
B24: Resa | C24: Injection | D24: -Electricity storage installations: • 100% exemption from injection tariffs
B25: Ores | C25: Offtake | D25: -Electricity storage installations: • PSO tariff based on net active energy consumed over a calendar year (not gross consumption) • Surcharges tariff based on net active energy consumed over a calendar year (not gross consumption) • Correction and reimbursement processed in January of year Y+1
C26: Injection | D26: -Electricity storage installations: • 100% exemption from injection tariffs
B28: Split LO & HI hours
B29: Sibelga | C29: LO hours: Monday to Friday 10PM-7AM, Weekends & Holidays 24h/24
B30: Resa/Ores | C30: Quarter-hourly meter | D30: LO hours: Monday to Friday 10:30PM-7:30AM, Weekends & Holidays 24h/24
C31: Monthly or annual meter | D31: LO hours: Monday to Friday 10PM-7AM, Weekends & Holidays 24h/24

Sheet Details
A1: Assume 1.5 cycle per day = 3 MWh charge + 3 MWh discharge | D1: Input
D2: Peak demand (MW) | E2: 1
D3: E1 | E3: =0.63+327.45/(885+(E2*1000)) -> 0.80371353
A4: Code | B4: System Operator | C4: Voltage level | D4: Connection | E4: Link to tariffs | F4: Total costs for 1 MW, 2h BESS incl. regulatory exemptions | G4: Exemptions | H4: Total costs for 1 MW, 2h BESS excl. regulatory exemtions | I4: Injection costs | J4: Note | K4: Contracted Yearly | L4: Peak Monthly | M4: Note | N4: Peak Yearly | O4: Note | P4: Volumetric | Q4: Note | R4: Other costs | S4: Note | T4: Offtake costs | U4: Note | V4: Contracted Capacity | W4: Note | X4: Peak Monthly | Y4: Note | Z4: Peak Yearly | AA4: Note | AB4: Volumetric | AC4: Note | AD4: Other costs | AE4: Note
I5: Fixed | T5: Fixed
B6: - | C6: - | D6: - | E6: - | F6: k€/y | H6: k€/y | I6: k€/y | J6: - | K6: k€/MVA/y | L6: k€/MW/y | M6: - | O6: - | P6: k€/MWh | Q6: - | R6: - | S6: - | T6: k€/y | U6: - | V6: k€/MVA/y | X6: k€/MW/y | Y6: - | Z6: k€/MW/y | AA6: - | AB6: k€/MWh | AC6: - | AD6: k€/MWh | AE6: -
A7: Elia - 110-380 | B7: Elia | C7: High - 110-380 kV | E7: Tariffs for 24-27 Exemption Electricity storage facilities | F7: =I7+K7+L7+P7*3*365+V7+T7 -> 7.5485 | G7: -Mobile load discount: For 'mobile load' access points, the monthly and yearly offtake peak tariff as well as the contracted yearly tariff is reduced by 7%. -Electricity storage facilities: New storage facilities (commissioned after July 1, 2018): 100% exemption from all transmission tariffs (except connection tariffs) for 10 years following initial commissioning. Expanded storage facilities (>7.5% increase in both capacity and energy vs. July 1, 2018): 80% exemption from transmission tariffs (except connection tariffs) for 5 years following recommissioning. The exemption can start after the first phase of expansion (capacity OR energy), but must be reimbursed within 2 months if the second phase is not completed within 3 years after the first phase ends. -Balancing/redispatching corrections: If Elia activates downward aFRR, mFRR, or redispatching energy that impacts the monthly or yearly offtake peak calculation, the monthly or yearly peak will be corrected based on this impact. | H7: =I7+K7+L7+P7*3*365+V7+T7+X7+Z7+(AB7+AD7)*3*365 -> 24.955915 | V7: 7.5485 | W7: Different tariffs for additional access points (they are a lot smaller) | X7: =0.395*12 -> 4.74 | Y7: monthly peak applied to the 11th measured peak of the month (only if specifically connected to the Elia grid or DSO connected to 30/36/70-kV network). Quarter-hours during the monthly peak demand-reduction period (April to September, weekends, 10 a.m. to 7 p.m.) are excluded from the monthly peak calculation. | Z7: 9.826 | AA7: Annual peak applied to the highest measured peak during the annual peak tariff period in the previous 12 months, after excluding the 10 highest peaks measured each month (only if specifically connected to the Elia grid or DSO connected to 30/36/70-kV network). The annual peak tariff period is defined as January to March and November to December, from 5 p.m. to 8 p.m., excluding weekends and public holidays. | AB7: =2.5949/1000 -> 0.0025949
A8: Elia - 30-70 | C8: High - 30-70 kV | F8: =I8+K8+L8+P8*3*365+V8+T8 -> 13.606 | G8: See above | H8: =I8+K8+L8+P8*3*365+V8+T8+X8+Z8+(AB8+AD8)*3*365 -> 40.09995 | V8: 13.606 | W8: See above | X8: =0.6072*12 -> 7.2864 | Y8: See above | Z8: 14.88 | AA8: See above | AB8: =3.9521/1000 -> 0.0039521
A9: Elia -Transfo < 30kV | C9: Tranformer output to MV (<30 kV) | F9: =I9+K9+L9+P9*3*365+V9+T9 -> 25.1504 | G9: See above | H9: =I9+K9+L9+P9*3*365+V9+T9+X9+Z9+(AB9+AD9)*3*365 -> 62.380055 | V9: 25.1504 | W9: See above | X9: =0.8237*12 -> 9.8844 | Y9: See above | Z9: 19.9574 | AA9: See above | AB9: =6.7469/1000 -> 0.0067469
A10: Fluvius - 26 - 36 - Post | B10: Fluvius | C10: >26-36 kV | D10: Post | E10: Tariffs 2026 Offtake Tariffs 2026 Injection | F10: =I10+K10+L10+P10*3*365+V10*0.2+T10+X10*0.2+Z10 -> 16.849324 | G10: EXEMPTIONS FOR OFFTAKE -Demand response service providers: Exemption for measured quarter-hour peaks (kW) during activation or control tests that Elia performs in the context of those demand response services. -Stand-alone stationary storage systems: • 80% reduction on the contracted capacity and peak monthly tariff (exceeding capacity tariff as well but not included in these calculations) • 100% exemption from volumetric tariff (tariff for PSO & surcharges) -Transit tariffs are 75% of the tariffs for the customer group to which the transit point belongs -The maximum tariff is 0.0596319 k€/MWh, excl.tariff for exceeding access capacity, additional reactive energy offtake, data management (fixed tariff) and it is not applicable to emergency power supplies, transit points, low voltage customers with analog meters and prosumers with reversing meters. Low voltage customers with peak measurement must pay a minimum contribution of €122.61/year, even if the maximum tariff applies. | H10: =I10+K10+L10+P10*3*365+V10+T10+X10+Z10+(AB10+AD10)*3*365 -> 76.397895 | I10: 0.05765 | J10: Data mgt fee | P10: 0.001751 | T10: 0.05765 | U10: Data mgt fee | V10: 30.90047 | X10: 43.182926 | AB10: =0.0002386+0.0000188 -> 0.0002574 | AC10: tariff for PSO & surcharges | AE10: Transit tariffs are 75% of the tariffs for the customer group to which the transit point belongs
A11: Fluvius - 26 - 36 - Grid | D11: Grid | F11: =I11+K11+L11+P11*3*365+V11*0.2+T11+X11*0.2+Z11 -> 9.3625621 | G11: EXEMPTIONS FOR INJECTION -Small-scale decentralized production (≤10 kVA): 100% exemption from the volumetric tariff -100% exemption from the fixed cost (data mgt) UNLESS seperate injection access point | H11: =I11+K11+L11+P11*3*365+V11+T11+X11+Z11+(AB11+AD11)*3*365 -> 42.73955 | I11: 0.05765 | J11: Data mgt fee | P11: 0.001751 | T11: =57.6459724/1000 -> 0.057645972 | U11: Data mgt fee | V11: 14.684942 | X11: 21.964663 | AB11: =0.0035086+0.0001967 -> 0.0037053 | AC11: See above | AE11: See above
A12: Fluvius - 1-26 - Post | C12: >1-26 kV | D12: Post | F12: =I12+K12+L12+P12*3*365+V12*0.2+T12+X12*0.2+Z12 -> 16.849324 | G12: See above | H12: =I12+K12+L12+P12*3*365+V12+T12+X12+Z12+(AB12+AD12)*3*365 -> 76.397895 | I12: 0.05765 | J12: Data mgt fee | P12: 0.001751 | T12: 0.05765 | U12: Data mgt fee | V12: 30.90047 | X12: 43.182926 | AB12: =0.0002386+0.0000188 -> 0.0002574 | AC12: See above | AE12: See above
A13: Fluvius - 1-26 - Grid | D13: Grid | F13: =I13+K13+L13+P13*3*365+V13*0.2+T13+X13*0.2+Z13 -> 19.159025 | G13: See above | H13: =I13+K13+L13+P13*3*365+V13+T13+X13+Z13+(AB13+AD13)*3*365 -> 91.812512 | I13: 0.05765 | J13: Data mgt fee | P13: 0.001751 | T13: 0.05765 | U13: Data mgt fee | V13: 35.178839 | X13: 50.453059 | AB13: =0.003587+0.0002011 -> 0.0037881 | AC13: See above | AE13: See above
A14: Sibelga - 1-26 - Main | B14: Sibelga | C14: 1-26 kV | D14: Main Supply | E14: Tariff 2026 Terms of application Simulator | F14: =I14+K14+L14+P14*3*365+V14+T14+X14+Z14+(AB14+AD14)*3*365 -> 86.591843 | H14: =I14+K14+L14+P14*3*365+V14+T14+X14+Z14+(AB14+AD14)*3*365 -> 86.591843 | T14: =543.11/1000 -> 0.54311 | X14: =59.98*E3 -> 48.206737 | Y14: capacity rate multiplied by degression factor E1 Charged monthly based on the highest 15-minute peak power (kW) during peak hours in the past 12 months (including current month) | AB14: =AVERAGE(0.0047539,0.0028523) -> 0.0038031 | AC14: fees are split into HI and LO HI: 0.0047539 LO: 0.002852 --> average taken | AD14: =0.0002504+0.0043665+0.0013085+0.0033901+0.0214403 -> 0.0307558 | AE14: Surcharges: -Pension -Road compensation -Corporate tax -PSO -Transmission
D15: Backup Supply | F15: =I15+K15+L15+P15*3*365+V15+T15+X15+Z15+(AB15+AD15)*3*365 -> 62.488474 | H15: =I15+K15+L15+P15*3*365+V15+T15+X15+Z15+(AB15+AD15)*3*365 -> 62.488474 | T15: =543.11/1000 -> 0.54311 | X15: =29.99*E3 -> 24.103369 | Y15: capacity rate multiplied by degression factor E1 Charged monthly based on the highest 15-minute peak power (kW) during peak hours in the past 12 months (including current month) | AB15: =AVERAGE(0.0047539,0.0028523) -> 0.0038031 | AC15: fees are split into HI and LO HI: 0.0047539 LO: 0.002852 --> average taken | AD15: =0.0002504+0.0043665+0.0013085+0.0033901+0.0214403 -> 0.0307558 | AE15: Surcharges: -Pension -Road compensation -Corporate tax -PSO -Transmission
A16: RESA - MT - Post | B16: Resa | C16: MT | D16: Post (T-MT) | E16: Tariff 2026 Offtake Tariff 2026 Injection | F16: =T16+X16+Z16+(AB16+AD16)*3*365 -> 10.301504 | G16: EXEMPTIONS FOR OFFTAKE -Emergency power supplies: • 100% exemption from capacity term • Maximum usage duration: 500 hours per year -Shared energy within the same building: • 80% reduction on the proportional term (volumetric tariff) for energy shared within the same building • No reduction applies to residual electricity consumed -Flexibility activation: When flexibility is activated, the capacity requested by the distribution system operator is deducted from the peak of the relevant quarter-hour | H16: =I16+K16+L16+P16*3*365+V16+T16+X16+Z16+(AB16+AD16)*3*365 -> 11.650051 | I16: =877.58/1000 -> 0.87758 | K16: 0.4709669 | T16: =906.55/1000 -> 0.90655 | U16: Calculated pro-rata based on the number of days covered by the billing period | X16: =0.4883477*12*(2/3) -> 3.9067816 | Y16: Multiply by 2/3 of 11th highest quarterly peak of the month OR (if insufficient data) multiply by 2/3 of the maximum measured peak power during the month Source | Z16: =0.2441738*(1/3) -> 0.081391267 | AA16: Multiply by 1/3 of highest monthly peak from the past 12 months Source | AB16: =AVERAGE(0.00056,0.000224) -> 0.000392 | AC16: fees are split into HI and LO: HI: 0.0005600 LO: 0.0002240 | AD16: =0.0009193+0.0032333+0.0001469+0+0.0002462 -> 0.0045457 | AE16: Surcharges: -PSO -Road tax -Corporate tax -Other local, regional, provincial taxes -Regulatory balances
A17: RESA - MT - Grid | D17: Grid (MT) | F17: =T17+X17+Z17+(AB17+AD17)*3*365 -> 46.451664 | G17: EXEMPTIONS FOR INJECTION -Production installations with anti-return device: • 100% exemption from injection tariffs for production installations where injection to the distribution network is made permanently technically impossible by an 'anti-return' device -Electricity storage installations: • 100% exemption from injection tariffs • When a production installation is connected downstream of the same access point as a storage installation (and injection is not made permanently technically impossible), only the storage installation benefits from this exemption - the production installation must still pay injection tariffs | H17: =I17+K17+L17+P17*3*365+V17+T17+X17+Z17+(AB17+AD17)*3*365 -> 47.160793 | I17: =665.23/1000 -> 0.66523 | K17: 0.0438992 | T17: =796.43/1000 -> 0.79643 | U17: See above | X17: =3.8666833*12*(2/3) -> 30.933466 | Y17: See above | Z17: =1.9333416*(1/3) -> 0.6444472 | AA17: See above | AB17: =AVERAGE(0.0071277,0.0028511) -> 0.0049894 | AC17: fees are split into HI and LO: HI: 0.0071277 LO: 0.0028511 | AD17: =0.0009193+0.0032333+0.0013882+0+0.0023258 -> 0.0078666 | AE17: See above
A18: ORES - MT - Post | B18: Ores | C18: MT | D18: Post (T-MT) | E18: Tariff 2026 Offtake Tariff 2026 Injection | F18: =T18+X18+Z18+(AB18+AD18)*3*365*0.15 -> 4.8746822 | G18: EXEMPTIONS FOR OFFTAKE -Emergency power supplies: • 100% exemption from capacity term • Maximum usage duration: 500 hours per year -Shared energy within the same building: • 80% reduction on the proportional term (volumetric tariff) for energy shared within the same building • No reduction applies to residual electricity consumed -Flexibility activation: When flexibility is activated, the capacity requested by the distribution system operator is deducted from the peak of the relevant quarter-hour -Electricity storage installations: • PSO tariff based on net active energy consumed over a calendar year (not gross consumption) • Surcharges tariff based on net active energy consumed over a calendar year (not gross consumption) • Correction and reimbursement processed in January of year Y+1 | H18: =I18+K18+L18+P18*3*365+V18+T18+X18+Z18+(AB18+AD18)*3*365 -> 11.012869 | I18: =877.58/1000 -> 0.87758 | K18: 0.4709669 | T18: =875.69/1000 -> 0.87569 | X18: =0.3861749*12*(2/3) -> 3.0893992 | Y18: Multiply by 2/3 of 11th highest quarterly peak of the month OR (if insufficient data) multiply by 2/3 of the maximum measured peak power during the month Source | Z18: =0.1930874*(1/3) -> 0.064362467 | AA18: Multiply by 1/3 of highest monthly peak from the past 12 months Source | AB18: =AVERAGE(0.0001695,0.0000881) -> 0.0001288 | AC18: fees are split into HI and LO: HI: 0.0001695 LO: 0.0000881 | AD18: =0.0010523+0.0034069+0.0003103+0.0000353+0.0002124 -> 0.0050172 | AE18: Surcharges: -PSO -Road tax -Corporate tax -Other local, regional, provincial taxes -Regulatory balances
A19: ORES - MT - Grid | D19: Grid (MT) | F19: =T19+X19+Z19+(AB19+AD19)*3*365*0.15 -> 25.53039 | G19: EXEMPTIONS FOR INJECTION -Production installations with anti-return device: • 100% exemption from injection tariffs for production installations where injection to the distribution network is made permanently technically impossible by an 'anti-return' device -Electricity storage installations: • 100% exemption from injection tariffs • When a production installation is connected downstream of the same access point as a storage installation (and injection is not made permanently technically impossible), only the storage installation benefits from this exemption - the production installation must still pay injection tariffs | H19: =I19+K19+L19+P19*3*365+V19+T19+X19+Z19+(AB19+AD19)*3*365 -> 37.982048 | I19: =665.23/1000 -> 0.66523 | K19: 0.0438992 | T19: =637.34/1000 -> 0.63734 | X19: =2.7943885*12*(2/3) -> 22.355108 | Y19: See above | Z19: =1.3971943*(1/3) -> 0.46573143 | AA19: See above | AB19: =AVERAGE(0.0051818,0.002882) -> 0.0040319 | AC19: fees are split into HI and LO: HI: 0.0001695 LO: 0.0000881 | AD19: =0.0010738+0.0034069+0.001202+0.000036+0.0028656 -> 0.0085843 | AE19: See above

Sheet BESS Example
B2: Assumtions
B3: BESS Size | C3: 1 | D3: MW
B4: BESS Size | C4: 2 | D4: MWh
B5: Cycles per day | C5: 1.5 | D5: c/day
B6: Efficiency | C6: 0.88
B8: Without exemption for BESS
B9: k€/MWBESS/y | C9: Grid connection | D9: Volumetric Offtake + Injection | E9: Offtake Peak Yearly + Monthly | F9: Fixed Offtake + Injection | G9: Offtake Contracted | H9: Injection Contracted | I9: Total
C10: Elia - 110-380 | D10: =IFERROR(__xludf.DUMMYFUNCTION("FILTER(Details!P:P,Details!$A:$A=$C10)*365*$C$4*$C$5/$C$3*SQRT($C$6) + FILTER(Details!AB:AB,Details!$A:$A=$C10)*365*$C$4*$C$5/$C$3/SQRT($C$6)"),3.0289591003196743) -> 3.0289591 | E10: =IFERROR(__xludf.DUMMYFUNCTION("FILTER(Details!X:X,Details!$A:$A=$C10) + FILTER(Details!Z:Z,Details!$A:$A=$C10)"),14.566) -> 14.566 | F10: =IFERROR(__xludf.DUMMYFUNCTION("FILTER(Details!I:I,Details!$A:$A=$C10)/$C$3 + FILTER(Details!T:T,Details!$A:$A=$C10)/$C$3"),0.0) -> 0 | G10: =IFERROR(__xludf.DUMMYFUNCTION("FILTER(Details!V:V,Details!$A:$A=$C10)"),7.5485) -> 7.5485 | H10: =IFERROR(__xludf.DUMMYFUNCTION("FILTER(Details!K:K,Details!$A:$A=$C10)"),"") | I10: =sum(D10:H10) -> 25.143459
C11: Elia - 30-70 | D11: =IFERROR(__xludf.DUMMYFUNCTION("FILTER(Details!P:P,Details!$A:$A=$C11)*365*$C$4*$C$5/$C$3*SQRT($C$6) + FILTER(Details!AB:AB,Details!$A:$A=$C11)*365*$C$4*$C$5/$C$3/SQRT($C$6)"),4.613183267321818) -> 4.6131833 | E11: =IFERROR(__xludf.DUMMYFUNCTION("FILTER(Details!X:X,Details!$A:$A=$C11) + FILTER(Details!Z:Z,Details!$A:$A=$C11)"),22.1664) -> 22.1664 | F11: =IFERROR(__xludf.DUMMYFUNCTION("FILTER(Details!I:I,Details!$A:$A=$C11)/$C$3 + FILTER(Details!T:T,Details!$A:$A=$C11)/$C$3"),0.0) -> 0 | G11: =IFERROR(__xludf.DUMMYFUNCTION("FILTER(Details!V:V,Details!$A:$A=$C11)"),13.606) -> 13.606 | H11: =IFERROR(__xludf.DUMMYFUNCTION("FILTER(Details!K:K,Details!$A:$A=$C11)"),"") | I11: =sum(D11:H11) -> 40.385583
C12: Elia -Transfo < 30kV | D12: =IFERROR(__xludf.DUMMYFUNCTION("FILTER(Details!P:P,Details!$A:$A=$C12)*365*$C$4*$C$5/$C$3*SQRT($C$6) + FILTER(Details!AB:AB,Details!$A:$A=$C12)*365*$C$4*$C$5/$C$3/SQRT($C$6)"),7.875480424658683) -> 7.8754804 | E12: =IFERROR(__xludf.DUMMYFUNCTION("FILTER(Details!X:X,Details!$A:$A=$C12) + FILTER(Details!Z:Z,Details!$A:$A=$C12)"),29.8418) -> 29.8418 | F12: =IFERROR(__xludf.DUMMYFUNCTION("FILTER(Details!I:I,Details!$A:$A=$C12)/$C$3 + FILTER(Details!T:T,Details!$A:$A=$C12)/$C$3"),0.0) -> 0 | G12: =IFERROR(__xludf.DUMMYFUNCTION("FILTER(Details!V:V,Details!$A:$A=$C12)"),25.1504) -> 25.1504 | H12: =IFERROR(__xludf.DUMMYFUNCTION("FILTER(Details!K:K,Details!$A:$A=$C12)"),"") | I12: =sum(D12:H12) -> 62.86768
C13: Fluvius - 26 - 36 - Post | D13: =IFERROR(__xludf.DUMMYFUNCTION("FILTER(Details!P:P,Details!$A:$A=$C13)*365*$C$4*$C$5/$C$3*SQRT($C$6) + FILTER(Details!AB:AB,Details!$A:$A=$C13)*365*$C$4*$C$5/$C$3/SQRT($C$6)"),2.0990853485386203) -> 2.0990853 | E13: =IFERROR(__xludf.DUMMYFUNCTION("FILTER(Details!X:X,Details!$A:$A=$C13) + FILTER(Details!Z:Z,Details!$A:$A=$C13)"),43.1829264) -> 43.182926 | F13: =IFERROR(__xludf.DUMMYFUNCTION("FILTER(Details!I:I,Details!$A:$A=$C13)/$C$3 + FILTER(Details!T:T,Details!$A:$A=$C13)/$C$3"),0.1153) -> 0.1153 | G13: =IFERROR(__xludf.DUMMYFUNCTION("FILTER(Details!V:V,Details!$A:$A=$C13)"),30.9004704) -> 30.90047 | H13: =IFERROR(__xludf.DUMMYFUNCTION("FILTER(Details!K:K,Details!$A:$A=$C13)"),"") | I13: =sum(D13:H13) -> 76.297782
C14: Fluvius - 26 - 36 - Grid | D14: =IFERROR(__xludf.DUMMYFUNCTION("FILTER(Details!P:P,Details!$A:$A=$C14)*365*$C$4*$C$5/$C$3*SQRT($C$6) + FILTER(Details!AB:AB,Details!$A:$A=$C14)*365*$C$4*$C$5/$C$3/SQRT($C$6)"),6.123729104364359) -> 6.1237291 | E14: =IFERROR(__xludf.DUMMYFUNCTION("FILTER(Details!X:X,Details!$A:$A=$C14) + FILTER(Details!Z:Z,Details!$A:$A=$C14)"),21.9646632) -> 21.964663 | F14: =IFERROR(__xludf.DUMMYFUNCTION("FILTER(Details!I:I,Details!$A:$A=$C14)/$C$3 + FILTER(Details!T:T,Details!$A:$A=$C14)/$C$3"),0.1152959724) -> 0.11529597 | G14: =IFERROR(__xludf.DUMMYFUNCTION("FILTER(Details!V:V,Details!$A:$A=$C14)"),14.6849424) -> 14.684942 | H14: =IFERROR(__xludf.DUMMYFUNCTION("FILTER(Details!K:K,Details!$A:$A=$C14)"),"") | I14: =sum(D14:H14) -> 42.888631
C15: Fluvius - 1-26 - Post | D15: =IFERROR(__xludf.DUMMYFUNCTION("FILTER(Details!P:P,Details!$A:$A=$C15)*365*$C$4*$C$5/$C$3*SQRT($C$6) + FILTER(Details!AB:AB,Details!$A:$A=$C15)*365*$C$4*$C$5/$C$3/SQRT($C$6)"),2.0990853485386203) -> 2.0990853 | E15: =IFERROR(__xludf.DUMMYFUNCTION("FILTER(Details!X:X,Details!$A:$A=$C15) + FILTER(Details!Z:Z,Details!$A:$A=$C15)"),43.1829264) -> 43.182926 | F15: =IFERROR(__xludf.DUMMYFUNCTION("FILTER(Details!I:I,Details!$A:$A=$C15)/$C$3 + FILTER(Details!T:T,Details!$A:$A=$C15)/$C$3"),0.1153) -> 0.1153 | G15: =IFERROR(__xludf.DUMMYFUNCTION("FILTER(Details!V:V,Details!$A:$A=$C15)"),30.9004704) -> 30.90047 | H15: =IFERROR(__xludf.DUMMYFUNCTION("FILTER(Details!K:K,Details!$A:$A=$C15)"),"") | I15: =sum(D15:H15) -> 76.297782
C16: Fluvius - 1-26 - Grid | D16: =IFERROR(__xludf.DUMMYFUNCTION("FILTER(Details!P:P,Details!$A:$A=$C16)*365*$C$4*$C$5/$C$3*SQRT($C$6) + FILTER(Details!AB:AB,Details!$A:$A=$C16)*365*$C$4*$C$5/$C$3/SQRT($C$6)"),6.2203793851098474) -> 6.2203794 | E16: =IFERROR(__xludf.DUMMYFUNCTION("FILTER(Details!X:X,Details!$A:$A=$C16) + FILTER(Details!Z:Z,Details!$A:$A=$C16)"),50.4530592) -> 50.453059 | F16: =IFERROR(__xludf.DUMMYFUNCTION("FILTER(Details!I:I,Details!$A:$A=$C16)/$C$3 + FILTER(Details!T:T,Details!$A:$A=$C16)/$C$3"),0.1153) -> 0.1153 | G16: =IFERROR(__xludf.DUMMYFUNCTION("FILTER(Details!V:V,Details!$A:$A=$C16)"),35.1788388) -> 35.178839 | H16: =IFERROR(__xludf.DUMMYFUNCTION("FILTER(Details!K:K,Details!$A:$A=$C16)"),"") | I16: =sum(D16:H16) -> 91.967577
C17: Sibelga - 1-26 - Main | D17: =IFERROR(__xludf.DUMMYFUNCTION("FILTER(Details!P:P,Details!$A:$A=$C17)*365*$C$4*$C$5/$C$3*SQRT($C$6) + FILTER(Details!AB:AB,Details!$A:$A=$C17)*365*$C$4*$C$5/$C$3/SQRT($C$6) + FILTER(Details!AD:AD,Details!$A:$A=$C17)*365*$C$4*$C$5/$C$3"),38.11686045293682) -> 38.11686 | E17: =IFERROR(__xludf.DUMMYFUNCTION("FILTER(Details!X:X,Details!$A:$A=$C17) + FILTER(Details!Z:Z,Details!$A:$A=$C17)"),48.2067374005305) -> 48.206737 | F17: =IFERROR(__xludf.DUMMYFUNCTION("FILTER(Details!I:I,Details!$A:$A=$C17)/$C$3 + FILTER(Details!T:T,Details!$A:$A=$C17)/$C$3"),0.54311) -> 0.54311 | G17: =IFERROR(__xludf.DUMMYFUNCTION("FILTER(Details!V:V,Details!$A:$A=$C17)"),"") | H17: =IFERROR(__xludf.DUMMYFUNCTION("FILTER(Details!K:K,Details!$A:$A=$C17)"),"") | I17: =sum(D17:H17) -> 86.866708
C18: RESA - MT - Post | D18: =IFERROR(__xludf.DUMMYFUNCTION("FILTER(Details!P:P,Details!$A:$A=$C18)*365*$C$4*$C$5/$C$3*SQRT($C$6) + FILTER(Details!AB:AB,Details!$A:$A=$C18)*365*$C$4*$C$5/$C$3/SQRT($C$6) + FILTER(Details!AD:AD,Details!$A:$A=$C18)*365*$C$4*$C$5/$C$3"),5.435112877442412) -> 5.4351129 | E18: =IFERROR(__xludf.DUMMYFUNCTION("FILTER(Details!X:X,Details!$A:$A=$C18) + FILTER(Details!Z:Z,Details!$A:$A=$C18)"),3.988172866666666) -> 3.9881729 | F18: =IFERROR(__xludf.DUMMYFUNCTION("FILTER(Details!I:I,Details!$A:$A=$C18)/$C$3 + FILTER(Details!T:T,Details!$A:$A=$C18)/$C$3"),1.78413) -> 1.78413 | G18: =IFERROR(__xludf.DUMMYFUNCTION("FILTER(Details!V:V,Details!$A:$A=$C18)"),"") | H18: =IFERROR(__xludf.DUMMYFUNCTION("FILTER(Details!K:K,Details!$A:$A=$C18)"),0.4709669) -> 0.4709669 | I18: =sum(D18:H18) -> 11.678383 | S18: =(43-58)/58 -> -0.25862069 | T18: Fluvius - 26 - 36 - Grid | V18: Peak & Contracted
C19: RESA - MT - Grid | D19: =IFERROR(__xludf.DUMMYFUNCTION("FILTER(Details!P:P,Details!$A:$A=$C19)*365*$C$4*$C$5/$C$3*SQRT($C$6) + FILTER(Details!AB:AB,Details!$A:$A=$C19)*365*$C$4*$C$5/$C$3/SQRT($C$6) + + FILTER(Details!AD:AD,Details!$A:$A=$C19)*365*$C$4*$C$5/$C$3"),14.437923506661136) -> 14.437924 | E19: =IFERROR(__xludf.DUMMYFUNCTION("FILTER(Details!X:X,Details!$A:$A=$C19) + FILTER(Details!Z:Z,Details!$A:$A=$C19)"),31.5779136) -> 31.577914 | F19: =IFERROR(__xludf.DUMMYFUNCTION("FILTER(Details!I:I,Details!$A:$A=$C19)/$C$3 + FILTER(Details!T:T,Details!$A:$A=$C19)/$C$3"),1.46166) -> 1.46166 | G19: =IFERROR(__xludf.DUMMYFUNCTION("FILTER(Details!V:V,Details!$A:$A=$C19)"),"") | H19: =IFERROR(__xludf.DUMMYFUNCTION("FILTER(Details!K:K,Details!$A:$A=$C19)"),0.0438992) -> 0.0438992 | I19: =sum(D19:H19) -> 47.521396 | S19: =(92-102)/102 -> -0.098039216 | T19: Fluvius - 1-26 - Grid | V19: Peak & Contracted
C20: ORES - MT - Post | D20: =IFERROR(__xludf.DUMMYFUNCTION("FILTER(Details!P:P,Details!$A:$A=$C20)*365*$C$4*$C$5/$C$3*SQRT($C$6) + FILTER(Details!AB:AB,Details!$A:$A=$C20)*365*$C$4*$C$5/$C$3/SQRT($C$6) + FILTER(Details!AD:AD,Details!$A:$A=$C20)*365*$C$4*$C$5/$C$3"),5.64417888115965) -> 5.6441789 | E20: =IFERROR(__xludf.DUMMYFUNCTION("FILTER(Details!X:X,Details!$A:$A=$C20) + FILTER(Details!Z:Z,Details!$A:$A=$C20)"),3.1537616666666666) -> 3.1537617 | F20: =IFERROR(__xludf.DUMMYFUNCTION("FILTER(Details!I:I,Details!$A:$A=$C20)/$C$3 + FILTER(Details!T:T,Details!$A:$A=$C20)/$C$3"),1.75327) -> 1.75327 | G20: =IFERROR(__xludf.DUMMYFUNCTION("FILTER(Details!V:V,Details!$A:$A=$C20)"),"") | H20: =IFERROR(__xludf.DUMMYFUNCTION("FILTER(Details!K:K,Details!$A:$A=$C20)"),0.4709669) -> 0.4709669 | I20: =sum(D20:H20) -> 11.022177 | S20: =(87-80)/80 -> 0.0875 | T20: Sibelga - 1-26 - Main | V20: Peak
C21: ORES - MT - Grid | D21: =IFERROR(__xludf.DUMMYFUNCTION("FILTER(Details!P:P,Details!$A:$A=$C21)*365*$C$4*$C$5/$C$3*SQRT($C$6) + FILTER(Details!AB:AB,Details!$A:$A=$C21)*365*$C$4*$C$5/$C$3/SQRT($C$6) + FILTER(Details!AD:AD,Details!$A:$A=$C21)*365*$C$4*$C$5/$C$3"),14.106140226301164) -> 14.10614 | E21: =IFERROR(__xludf.DUMMYFUNCTION("FILTER(Details!X:X,Details!$A:$A=$C21) + FILTER(Details!Z:Z,Details!$A:$A=$C21)"),22.820839433333333) -> 22.820839 | F21: =IFERROR(__xludf.DUMMYFUNCTION("FILTER(Details!I:I,Details!$A:$A=$C21)/$C$3 + FILTER(Details!T:T,Details!$A:$A=$C21)/$C$3"),1.30257) -> 1.30257 | G21: =IFERROR(__xludf.DUMMYFUNCTION("FILTER(Details!V:V,Details!$A:$A=$C21)"),"") | H21: =IFERROR(__xludf.DUMMYFUNCTION("FILTER(Details!K:K,Details!$A:$A=$C21)"),0.0438992) -> 0.0438992 | I21: =sum(D21:H21) -> 38.273449
B23: With exemption for BESS
B24: k€/MWBESS/y | C24: Grid connection | D24: Volumetric Offtake + Injection | E24: Offtake Peak Yearly + Monthly | F24: Fixed Offtake + Injection | G24: Offtake Contracted | H24: Injection Contracted | I24: Total
C25: Elia - 110-380 | D25: =IFERROR(__xludf.DUMMYFUNCTION("FILTER(Details!P:P,Details!$A:$A=$C25)*365*$C$4*$C$5/$C$3*SQRT($C$6)"),0.0) -> 0 | F25: =IFERROR(__xludf.DUMMYFUNCTION("(FILTER(Details!I:I,Details!$A:$A=$C25)/$C$3) + (FILTER(Details!T:T,Details!$A:$A=$C25)/$C$3)"),0.0) -> 0 | G25: =IFERROR(__xludf.DUMMYFUNCTION("FILTER(Details!V:V,Details!$A:$A=$C25)"),7.5485) -> 7.5485 | H25: =IFERROR(__xludf.DUMMYFUNCTION("FILTER(Details!K:K,Details!$A:$A=$C25)"),"") | I25: =sum(D25:H25) -> 7.5485
C26: Elia - 30-70 | D26: =IFERROR(__xludf.DUMMYFUNCTION("FILTER(Details!P:P,Details!$A:$A=$C26)*365*$C$4*$C$5/$C$3*SQRT($C$6)"),0.0) -> 0 | F26: =IFERROR(__xludf.DUMMYFUNCTION("(FILTER(Details!I:I,Details!$A:$A=$C26)/$C$3) + (FILTER(Details!T:T,Details!$A:$A=$C26)/$C$3)"),0.0) -> 0 | G26: =IFERROR(__xludf.DUMMYFUNCTION("FILTER(Details!V:V,Details!$A:$A=$C26)"),13.606) -> 13.606 | H26: =IFERROR(__xludf.DUMMYFUNCTION("FILTER(Details!K:K,Details!$A:$A=$C26)"),"") | I26: =sum(D26:H26) -> 13.606
C27: Elia -Transfo < 30kV | D27: =IFERROR(__xludf.DUMMYFUNCTION("FILTER(Details!P:P,Details!$A:$A=$C27)*365*$C$4*$C$5/$C$3*SQRT($C$6)"),0.0) -> 0 | F27: =IFERROR(__xludf.DUMMYFUNCTION("(FILTER(Details!I:I,Details!$A:$A=$C27)/$C$3) + (FILTER(Details!T:T,Details!$A:$A=$C27)/$C$3)"),0.0) -> 0 | G27: =IFERROR(__xludf.DUMMYFUNCTION("FILTER(Details!V:V,Details!$A:$A=$C27)"),25.1504) -> 25.1504 | H27: =IFERROR(__xludf.DUMMYFUNCTION("FILTER(Details!K:K,Details!$A:$A=$C27)"),"") | I27: =sum(D27:H27) -> 25.1504
C28: Fluvius - 26 - 36 - Post | D28: =IFERROR(__xludf.DUMMYFUNCTION("FILTER(Details!P:P,Details!$A:$A=$C28)*365*$C$4*$C$5/$C$3*SQRT($C$6)"),1.7986290410037309) -> 1.798629 | E28: =IFERROR(__xludf.DUMMYFUNCTION("(FILTER(Details!X:X,Details!$A:$A=$C28))*0.2 + FILTER(Details!Z:Z,Details!$A:$A=$C28)"),8.63658528) -> 8.6365853 | F28: =IFERROR(__xludf.DUMMYFUNCTION("(FILTER(Details!I:I,Details!$A:$A=$C28)/$C$3) + (FILTER(Details!T:T,Details!$A:$A=$C28)/$C$3)"),0.1153) -> 0.1153 | G28: =IFERROR(__xludf.DUMMYFUNCTION("(FILTER(Details!V:V,Details!$A:$A=$C28))*0.2"),6.18009408) -> 6.1800941 | H28: =IFERROR(__xludf.DUMMYFUNCTION("FILTER(Details!K:K,Details!$A:$A=$C28)"),"") | I28: =sum(D28:H28) -> 16.730608
C29: Fluvius - 26 - 36 - Grid | D29: =IFERROR(__xludf.DUMMYFUNCTION("FILTER(Details!P:P,Details!$A:$A=$C29)*365*$C$4*$C$5/$C$3*SQRT($C$6)"),1.7986290410037309) -> 1.798629 | E29: =IFERROR(__xludf.DUMMYFUNCTION("(FILTER(Details!X:X,Details!$A:$A=$C29))*0.2 + FILTER(Details!Z:Z,Details!$A:$A=$C29)"),4.392932640000001) -> 4.3929326 | F29: =IFERROR(__xludf.DUMMYFUNCTION("(FILTER(Details!I:I,Details!$A:$A=$C29)/$C$3) + (FILTER(Details!T:T,Details!$A:$A=$C29)/$C$3)"),0.1152959724) -> 0.11529597 | G29: =IFERROR(__xludf.DUMMYFUNCTION("(FILTER(Details!V:V,Details!$A:$A=$C29))*0.2"),2.93698848) -> 2.9369885 | H29: =IFERROR(__xludf.DUMMYFUNCTION("FILTER(Details!K:K,Details!$A:$A=$C29)"),"") | I29: =sum(D29:H29) -> 9.2438461
C30: Fluvius - 1-26 - Post | D30: =IFERROR(__xludf.DUMMYFUNCTION("FILTER(Details!P:P,Details!$A:$A=$C30)*365*$C$4*$C$5/$C$3*SQRT($C$6)"),1.7986290410037309) -> 1.798629 | E30: =IFERROR(__xludf.DUMMYFUNCTION("(FILTER(Details!X:X,Details!$A:$A=$C30))*0.2 + FILTER(Details!Z:Z,Details!$A:$A=$C30)"),8.63658528) -> 8.6365853 | F30: =IFERROR(__xludf.DUMMYFUNCTION("(FILTER(Details!I:I,Details!$A:$A=$C30)/$C$3) + (FILTER(Details!T:T,Details!$A:$A=$C30)/$C$3)"),0.1153) -> 0.1153 | G30: =IFERROR(__xludf.DUMMYFUNCTION("(FILTER(Details!V:V,Details!$A:$A=$C30))*0.2"),6.18009408) -> 6.1800941 | H30: =IFERROR(__xludf.DUMMYFUNCTION("FILTER(Details!K:K,Details!$A:$A=$C30)"),"") | I30: =sum(D30:H30) -> 16.730608
C31: Fluvius - 1-26 - Grid | D31: =IFERROR(__xludf.DUMMYFUNCTION("FILTER(Details!P:P,Details!$A:$A=$C31)*365*$C$4*$C$5/$C$3*SQRT($C$6)"),1.7986290410037309) -> 1.798629 | E31: =IFERROR(__xludf.DUMMYFUNCTION("(FILTER(Details!X:X,Details!$A:$A=$C31))*0.2 + FILTER(Details!Z:Z,Details!$A:$A=$C31)"),10.090611840000001) -> 10.090612 | F31: =IFERROR(__xludf.DUMMYFUNCTION("(FILTER(Details!I:I,Details!$A:$A=$C31)/$C$3) + (FILTER(Details!T:T,Details!$A:$A=$C31)/$C$3)"),0.1153) -> 0.1153 | G31: =IFERROR(__xludf.DUMMYFUNCTION("(FILTER(Details!V:V,Details!$A:$A=$C31))*0.2"),7.035767760000001) -> 7.0357678 | H31: =IFERROR(__xludf.DUMMYFUNCTION("FILTER(Details!K:K,Details!$A:$A=$C31)"),"") | I31: =sum(D31:H31) -> 19.040309
C32: Sibelga - 1-26 - Main | D32: =IFERROR(__xludf.DUMMYFUNCTION("FILTER(Details!P:P,Details!$A:$A=$C32)*365*$C$4*$C$5/$C$3*SQRT($C$6) + FILTER(Details!AB:AB,Details!$A:$A=$C32)*365*$C$4*$C$5/$C$3/SQRT($C$6) + FILTER(Details!AD:AD,Details!$A:$A=$C32)*365*$C$4*$C$5/$C$3"),38.11686045293682) -> 38.11686 | E32: =IFERROR(__xludf.DUMMYFUNCTION("(FILTER(Details!X:X,Details!$A:$A=$C32)) + FILTER(Details!Z:Z,Details!$A:$A=$C32)"),48.2067374005305) -> 48.206737 | F32: =IFERROR(__xludf.DUMMYFUNCTION("(FILTER(Details!I:I,Details!$A:$A=$C32)/$C$3) + (FILTER(Details!T:T,Details!$A:$A=$C32)/$C$3)"),0.54311) -> 0.54311 | G32: =IFERROR(__xludf.DUMMYFUNCTION("FILTER(Details!V:V,Details!$A:$A=$C32)"),"") | H32: =IFERROR(__xludf.DUMMYFUNCTION("FILTER(Details!K:K,Details!$A:$A=$C32)"),"") | I32: =sum(D32:H32) -> 86.866708
C33: RESA - MT - Post | D33: =IFERROR(__xludf.DUMMYFUNCTION("FILTER(Details!P:P,Details!$A:$A=$C33)*365*$C$4*$C$5/$C$3 + FILTER(Details!AB:AB,Details!$A:$A=$C33)*365*$C$4*$C$5/$C$3 + FILTER(Details!AD:AD,Details!$A:$A=$C33)*365*$C$4*$C$5/$C$3"),5.406781500000001) -> 5.4067815 | E33: =IFERROR(__xludf.DUMMYFUNCTION("FILTER(Details!X:X,Details!$A:$A=$C33) + FILTER(Details!Z:Z,Details!$A:$A=$C33)"),3.988172866666666) -> 3.9881729 | F33: =IFERROR(__xludf.DUMMYFUNCTION("FILTER(Details!T:T,Details!$A:$A=$C33)/$C$3"),0.90655) -> 0.90655 | G33: =IFERROR(__xludf.DUMMYFUNCTION("FILTER(Details!V:V,Details!$A:$A=$C33)"),"") | H33: =IFERROR(__xludf.DUMMYFUNCTION("FILTER(Details!K:K,Details!$A:$A=$C33)"),0.4709669) -> 0.4709669 | I33: =sum(D33:H33) -> 10.772471
C34: RESA - MT - Grid | D34: =IFERROR(__xludf.DUMMYFUNCTION("FILTER(Details!P:P,Details!$A:$A=$C34)*365*$C$4*$C$5/$C$3*SQRT($C$6) + FILTER(Details!AB:AB,Details!$A:$A=$C34)*365*$C$4*$C$5/$C$3/SQRT($C$6)"),5.823996506661137) -> 5.8239965 | E34: =IFERROR(__xludf.DUMMYFUNCTION("FILTER(Details!X:X,Details!$A:$A=$C34) + FILTER(Details!Z:Z,Details!$A:$A=$C34)"),31.5779136) -> 31.577914 | F34: =IFERROR(__xludf.DUMMYFUNCTION("FILTER(Details!T:T,Details!$A:$A=$C34)/$C$3"),0.79643) -> 0.79643 | G34: =IFERROR(__xludf.DUMMYFUNCTION("FILTER(Details!V:V,Details!$A:$A=$C34)"),"") | H34: =IFERROR(__xludf.DUMMYFUNCTION("FILTER(Details!K:K,Details!$A:$A=$C34)"),0.0438992) -> 0.0438992 | I34: =sum(D34:H34) -> 38.242239
C35: ORES - MT - Post | D35: =IFERROR(__xludf.DUMMYFUNCTION("FILTER(Details!P:P,Details!$A:$A=$C35)*365*$C$4*$C$5/$C$3*SQRT($C$6) + (FILTER(Details!AB:AB,Details!$A:$A=$C35)*365*$C$4*$C$5/$C$3/SQRT($C$6))*0.15 + (FILTER(Details!AD:AD,Details!$A:$A=$C35)*365*$C$4*$C$5/$C$3)*0.15"),0.8466268321739474) -> 0.84662683 | E35: =IFERROR(__xludf.DUMMYFUNCTION("FILTER(Details!X:X,Details!$A:$A=$C35) + FILTER(Details!Z:Z,Details!$A:$A=$C35)"),3.1537616666666666) -> 3.1537617 | F35: =IFERROR(__xludf.DUMMYFUNCTION("FILTER(Details!T:T,Details!$A:$A=$C35)/$C$3"),0.8756900000000001) -> 0.87569 | G35: =IFERROR(__xludf.DUMMYFUNCTION("FILTER(Details!V:V,Details!$A:$A=$C35)"),"") | H35: =IFERROR(__xludf.DUMMYFUNCTION("FILTER(Details!K:K,Details!$A:$A=$C35)"),0.4709669) -> 0.4709669 | I35: =sum(D35:H35) -> 5.3470454
C36: ORES - MT - Grid | D36: =IFERROR(__xludf.DUMMYFUNCTION("FILTER(Details!P:P,Details!$A:$A=$C36)*365*$C$4*$C$5/$C$3*SQRT($C$6) + (FILTER(Details!AB:AB,Details!$A:$A=$C36)*365*$C$4*$C$5/$C$3/SQRT($C$6))*0.15 + (FILTER(Details!AD:AD,Details!$A:$A=$C36)*365*$C$4*$C$5/$C$3)*0.15"),2.115921033945175) -> 2.115921 | E36: =IFERROR(__xludf.DUMMYFUNCTION("FILTER(Details!X:X,Details!$A:$A=$C36) + FILTER(Details!Z:Z,Details!$A:$A=$C36)"),22.820839433333333) -> 22.820839 | F36: =IFERROR(__xludf.DUMMYFUNCTION("FILTER(Details!T:T,Details!$A:$A=$C36)/$C$3"),0.63734) -> 0.63734 | G36: =IFERROR(__xludf.DUMMYFUNCTION("FILTER(Details!V:V,Details!$A:$A=$C36)"),"") | H36: =IFERROR(__xludf.DUMMYFUNCTION("FILTER(Details!K:K,Details!$A:$A=$C36)"),0.0438992) -> 0.0438992 | I36: =sum(D36:H36) -> 25.618
B38: Without vs. With Exemptions
B39: k€/MWBESS/y | C39: Grid connection | D39: Without exemtions | E39: With exemptions
C40: Elia - 110-380 | D40: =sum(D10:H10) -> 25.143459 | E40: =sum(D25:H25) -> 7.5485
C41: Elia - 30-70 | D41: =sum(D11:H11) -> 40.385583 | E41: =sum(D26:H26) -> 13.606
C42: Elia -Transfo < 30kV | D42: =sum(D12:H12) -> 62.86768 | E42: =sum(D27:H27) -> 25.1504
C43: Fluvius - 26 - 36 - Post | D43: =sum(D13:H13) -> 76.297782 | E43: =sum(D28:H28) -> 16.730608
C44: Fluvius - 26 - 36 - Grid | D44: =sum(D14:H14) -> 42.888631 | E44: =sum(D29:H29) -> 9.2438461
...

Sheet BACKEND Fees Database
A1: Key | B1: DSO/TSO Selection | C1: Region | D1: Voltage Level | E1: Connection Type | F1: Injection Fixed | G1: Injection Contracted | H1: Injection Peak Monthly | I1: Injection Peak Yearly | J1: Injection Volumentric | K1: Injection Other | L1: Offtake Fixed | M1: Offtake Contracted | N1: Offtake Peak Monthly | O1: Offtake Peak Yearly | P1: Offtake Volumetric | Q1: Offtake Other
F2: k€/y | G2: k€/MVA/y | H2: k€/MW/y | I2: k€/MW/y | J2: k€/MWh | K2: k€/MWh | L2: k€/y | M2: k€/MVA/y | N2: k€/MW/y | O2: k€/MW/y | P2: k€/MWh | Q2: k€/MWh
A3: Elia - 110-380 | B3: =LEFT(A3,FIND("-",A3) - 2) -> Elia | D3: 110-380 kV | M3: 7.5485 | N3: =0.395*12 -> 4.74 | O3: 9.826 | P3: =2.5949/1000 -> 0.0025949
A4: Elia - 30-70 | B4: =LEFT(A4,FIND("-",A4) - 2) -> Elia | D4: 30-70 kV | M4: 13.606 | N4: =0.6072*12 -> 7.2864 | O4: 14.88 | P4: =3.9521/1000 -> 0.0039521
A5: Elia -Transfo < 30kV | B5: =LEFT(A5,FIND("-",A5) - 2) -> Elia | D5: Transfo < 30 kV | M5: 25.1504 | N5: =0.8237*12 -> 9.8844 | O5: 19.9574 | P5: =6.7469/1000 -> 0.0067469
A6: Fluvius - Antwerpen - 26 - 36 - Post | B6: Fluvius | C6: Antwerpen | D6: 26-36 kV | E6: Post | F6: 0.05765 | J6: 0.001751 | L6: 0.05765 | M6: 41.641265 | N6: 56.845009 | P6: =0.0004587+0.0000282 -> 0.0004869
A7: Fluvius - Antwerpen - 26 - 36 - Grid | B7: Fluvius | C7: Antwerpen | D7: 26-36 kV | E7: Grid | F7: 0.05765 | J7: 0.001751 | L7: 0.05765 | M7: 33.658267 | N7: 54.303574 | P7: =0.0038921+0.0002446 -> 0.0041367
A8: Fluvius - Antwerpen - 1-26 - Post | B8: Fluvius | C8: Antwerpen | D8: 1-26 kV | E8: Post | F8: 0.05765 | J8: 0.001751 | L8: 0.05765 | M8: 41.641265 | N8: 56.845009 | P8: =0.0004587+0.0000282 -> 0.0004869
A9: Fluvius - Antwerpen - 1-26 - Grid | B9: Fluvius | C9: Antwerpen | D9: 1-26 kV | E9: Grid | F9: 0.05765 | J9: 0.001751 | L9: 0.05765 | M9: 33.658267 | N9: 54.303574 | P9: =0.0038921+0.0002446 -> 0.0041367
A10: Fluvius - Halle-Vilvoorde - 26 - 36 - Post | B10: Fluvius | C10: Halle-Vilvoorde | D10: 26-36 kV | E10: Post | F10: 0.05765 | J10: 0.001751 | L10: 0.05765 | M10: 25.93092 | N10: 57.44691 | P10: =0.0003705+0.0000315 -> 0.000402
A11: Fluvius - Halle-Vilvoorde - 26 - 36 - Grid | B11: Fluvius | C11: Halle-Vilvoorde | D11: 26-36 kV | E11: Grid | F11: 0.05765 | J11: 0.001751 | L11: 0.05765 | M11: 37.111009 | N11: 60.139519 | P11: =0.0047403+0.0003159 -> 0.0050562
A12: Fluvius - Halle-Vilvoorde - 1-26 - Post | B12: Fluvius | C12: Halle-Vilvoorde | D12: 1-26 kV | E12: Post | F12: 0.05765 | J12: 0.001751 | L12: 0.05765 | M12: 25.93092 | N12: 57.44691 | P12: =0.0003705+0.0000315 -> 0.000402
A13: Fluvius - Halle-Vilvoorde - 1-26 - Grid | B13: Fluvius | C13: Halle-Vilvoorde | D13: 1-26 kV | E13: Grid | F13: 0.05765 | J13: 0.001751 | L13: 0.05765 | M13: 37.111009 | N13: 60.139519 | P13: =0.0047403+0.0003159 -> 0.0050562
A14: Fluvius - Kempen - 26 - 36 - Post | B14: Fluvius | C14: Kempen | D14: 26-36 kV | E14: Post | F14: 0.05765 | J14: 0.001751 | L14: 0.05765 | M14: 28.621745 | N14: 39.187121 | P14: =0.0003764+0.0000178 -> 0.0003942
A15: Fluvius - Kempen - 26 - 36 - Grid | B15: Fluvius | C15: Kempen | D15: 26-36 kV | E15: Grid | F15: 0.05765 | J15: 0.001751 | L15: 0.05765 | M15: 6.8373552 | N15: 9.6334692 | P15: =0.0039994+0.0039994 -> 0.0079988
A16: Fluvius - Kempen - 1-26 - Post | B16: Fluvius | C16: Kempen | D16: 1-26 kV | E16: Post | F16: 0.05765 | J16: 0.001751 | L16: 0.05765 | M16: 28.6217 | N16: 39.187121 | P16: =0.0003764+0.0000178 -> 0.0003942
A17: Fluvius - Kempen - 1-26 - Grid | B17: Fluvius | C17: Kempen | D17: 1-26 kV | E17: Grid | F17: 0.05765 | J17: 0.001751 | L17: 0.05765 | M17: 31.567734 | N17: 46.863064 | P17: =0.0040283+0.0001922 -> 0.0042205
A18: Fluvius - Limburg - 26 - 36 - Post | B18: Fluvius | C18: Limburg | D18: 26-36 kV | E18: Post | F18: 0.05765 | J18: 0.001751 | L18: 0.05765 | M18: 25.644223 | N18: 32.240684 | P18: =0.0003627+0.0000356 -> 0.0003983
A19: Fluvius - Limburg - 26 - 36 - Grid | B19: Fluvius | C19: Limburg | D19: 26-36 kV | E19: Grid | F19: 0.05765 | J19: 0.001751 | L19: 0.05765 | M19: 30.406199 | N19: 32.240684 | P19: =0.0051533+0.000696 -> 0.0058493
A20: Fluvius - Limburg - 1-26 - Post | B20: Fluvius | C20: Limburg | D20: 1-26 kV | E20: Post | F20: 0.05765 | J20: 0.001751 | L20: 0.05765 | M20: 25.644223 | N20: 32.240684 | P20: =0.0003627+0.0000356 -> 0.0003983
A21: Fluvius - Limburg - 1-26 - Grid | B21: Fluvius | C21: Limburg | D21: 1-26 kV | E21: Grid | F21: 0.05765 | J21: 0.001751 | L21: 0.05765 | M21: 30.406199 | N21: 48.912096 | P21: =0.0051533+0.000696 -> 0.0058493
A22: Fluvius - Midden-Vlaanderen - 26 - 36 - Post | B22: Fluvius | C22: Midden-Vlaanderen | D22: 26-36 kV | E22: Post | F22: 0.05765 | J22: 0.001751 | L22: 0.05765 | M22: 30.90047 | N22: 43.182926 | P22: =0.0002386+0.0000188 -> 0.0002574
A23: Fluvius - Midden-Vlaanderen - 26 - 36 - Grid | B23: Fluvius | C23: Midden-Vlaanderen | D23: 26-36 kV | E23: Grid | F23: 0.05765 | J23: 0.001751 | L23: =57.6459724/1000 -> 0.057645972 | M23: 14.684942 | N23: 21.964663 | P23: =0.0035086+0.0001967 -> 0.0037053
A24: Fluvius - Midden-Vlaanderen - 1-26 - Post | B24: Fluvius | C24: Midden-Vlaanderen | D24: 1-26 kV | E24: Post | F24: 0.05765 | J24: 0.001751 | L24: 0.05765 | M24: 30.90047 | N24: 43.182926 | P24: =0.0002386+0.0000188 -> 0.0002574
A25: Fluvius - Midden-Vlaanderen - 1-26 - Grid | B25: Fluvius | C25: Midden-Vlaanderen | D25: 1-26 kV | E25: Grid | F25: 0.05765 | J25: 0.001751 | L25: 0.05765 | M25: 35.178839 | N25: 50.453059 | P25: =0.003587+0.0002011 -> 0.0037881
A26: Fluvius - West - 26 - 36 - Post | B26: Fluvius | C26: West | D26: 26-36 kV | E26: Post | F26: 0.05765 | J26: 0.001751 | L26: 0.05765 | M26: 35.676542 | N26: 46.19853 | P26: =0.0004068+0.0000226 -> 0.0004294
A27: Fluvius - West - 26 - 36 - Grid | B27: Fluvius | C27: West | D27: 26-36 kV | E27: Grid | F27: 0.05765 | J27: 0.001751 | L27: 0.05765 | M27: 41.6436 | N27: 59.761405 | P27: =0.0040025+0.0002219 -> 0.0042244
A28: Fluvius - West - 1-26 - Post | B28: Fluvius | C28: West | D28: 1-26 kV | E28: Post | F28: 0.05765 | J28: 0.001751 | L28: 0.05765 | M28: 35.676542 | N28: 46.19853 | P28: =0.0004068+0.0000226 -> 0.0004294
A29: Fluvius - West - 1-26 - Grid | B29: Fluvius | C29: West | D29: 1-26 kV | E29: Grid | F29: 0.05765 | J29: 0.001751 | L29: 0.05765 | M29: 41.6436 | N29: 59.761405 | P29: =0.0040025+0.0002219 -> 0.0042244
A30: Fluvius - Zenne-Dijle - 26 - 36 - Post | B30: Fluvius | C30: Zenne-Dijle | D30: 26-36 kV | E30: Post | F30: 0.05765 | J30: 0.001751 | L30: 0.05765 | M30: 37.965538 | N30: 47.964726 | P30: =0.000368+0.0000271 -> 0.0003951
A31: Fluvius - Zenne-Dijle - 26 - 36 - Grid | B31: Fluvius | C31: Zenne-Dijle | D31: 26-36 kV | E31: Grid | F31: 0.05765 | J31: 0.001751 | L31: 0.05765 | M31: 40.684499 | N31: 59.85696 | P31: =0.0039196+0.0003058 -> 0.0042254
A32: Fluvius - Zenne-Dijle - 1-26 - Post | B32: Fluvius | C32: Zenne-Dijle | D32: 1-26 kV | E32: Post | F32: 0.05765 | J32: 0.001751 | L32: 0.05765 | M32: 37.965538 | N32: 47.964726 | P32: =0.000368+0.0000271 -> 0.0003951
A33: Fluvius - Zenne-Dijle - 1-26 - Grid | B33: Fluvius | C33: Zenne-Dijle | D33: 1-26 kV | E33: Grid | F33: 0.05765 | J33: 0.001751 | L33: 0.05765 | M33: 40.684499 | N33: 59.85696 | P33: =0.0039196+0.0003058 -> 0.0042254
A34: Fluvius - Imewo - 26 - 36 - Post | B34: Fluvius | C34: Imewo | D34: 26-36 kV | E34: Post | F34: 0.05765 | J34: 0.001751 | L34: 0.05765 | M34: 39.477806 | N34: 46.471823 | P34: =0.0003588+0.0000169 -> 0.0003757
A35: Fluvius - Imewo - 26 - 36 - Grid | B35: Fluvius | C35: Imewo | D35: 26-36 kV | E35: Grid | F35: 0.05765 | J35: 0.001751 | L35: 0.05765 | M35: 36.105918 | N35: 54.228899 | P35: =0.0037033+0.0002193 -> 0.0039226
A36: Fluvius - Imewo - 1-26 - Post | B36: Fluvius | C36: Imewo | D36: 1-26 kV | E36: Post | F36: 0.05765 | J36: 0.001751 | L36: 0.05765 | M36: 39.477806 | N36: 46.471823 | P36: =0.0003588+0.0000169 -> 0.0003757
A37: Fluvius - Imewo - 1-26 - Grid | B37: Fluvius | C37: Imewo | D37: 1-26 kV | E37: Grid | F37: 0.05765 | J37: 0.001751 | L37: 0.05765 | M37: 36.105918 | N37: 54.228899 | P37: =0.0037033+0.0002193 -> 0.0039226
A38: Sibelga - 1-26 - Main | B38: =LEFT(A38,FIND("-",A38) - 2) -> Sibelga | D38: 1-26 kV | E38: Main | L38: =543.11/1000 -> 0.54311 | N38: =59.98*(0.63+327.45/(885+(Calculator!C10*1000))) -> 46.02239 | P38: =AVERAGE(0.0047539,0.0028523) -> 0.0038031 | Q38: =0.0002504+0.0043665+0.0013085+0.0033901+0.0214403 -> 0.0307558
A39: Sibelga - 1-26 - Backup | B39: =LEFT(A39,FIND("-",A39) - 2) -> Sibelga | D39: 1-26 kV | E39: Backup | L39: =543.11/1000 -> 0.54311 | N39: =29.99*(0.63+327.45/(885+(Calculator!C10*1000))) -> 23.011195 | P39: =AVERAGE(0.0047539,0.0028523) -> 0.0038031 | Q39: =0.0002504+0.0043665+0.0013085+0.0033901+0.0214403 -> 0.0307558
A40: Resa - MT - Post | B40: =LEFT(A40,FIND("-",A40) - 2) -> Resa | D40: MT | E40: Post | F40: =877.58/1000 -> 0.87758 | G40: 0.4709669 | L40: =906.55/1000 -> 0.90655 | N40: =0.4883477*12*(2/3) -> 3.9067816 | O40: =0.2441738*(1/3) -> 0.081391267 | P40: =AVERAGE(0.00056,0.000224) -> 0.000392 | Q40: =0.0009193+0.0032333+0.0001469+0+0.0002462 -> 0.0045457
...

Sheet BACKEND BESS Exemptions
A1: DSO/TSO Selection | B1: Fee Type | C1: Multiplier
A2: Elia | B2: Injection Fixed | C2: 1
A3: Elia | B3: Injection Contracted | C3: 1
A4: Elia | B4: Injection Peak Monthly | C4: 1
A5: Elia | B5: Injection Peak Yearly | C5: 0
A6: Elia | B6: Injection Volumetric | C6: 1
A7: Elia | B7: Injection Other | C7: 0
A8: Elia | B8: Offtake Fixed | C8: 1
A9: Elia | B9: Offtake Contracted | C9: 1
A10: Elia | B10: Offtake Peak Monthly | C10: 0
A11: Elia | B11: Offtake Peak Yearly | C11: 0
A12: Elia | B12: Offtake Volumetric | C12: 0
A13: Elia | B13: Offtake Other | C13: 0
... A61: Ores | B61: Offtake Other | C61: 0.15

Sheet BACKEND Connection Types
A1: Elia | B1: Fluvius | C1: Sibelga | D1: Ores | E1: Resa | F1: Fluvius Regions | G1: Elia | H1: Fluvius | I1: Sibelga | J1: Ores | K1: Resa
A2: 110-380 kV | B2: 26-36 kV | C2: 1-26 kV | D2: MT | E2: MT | F2: Antwerpen | H2: Post | I2: Main | J2: Post | K2: Post
A3: 30-70 kV | B3: 1-26 kV | F3: Halle-Vilvoorde | H3: Grid | I3: Backup | J3: Grid | K3: Grid
A4: Transfo < 30 kV | F4: Kempen
F5: Limburg
F6: Midden-Vlaanderen
F7: West
F8: Zenne-Dijle
F9: Imewo
